2025-10-27 20:05:12,362 ERROR: Exception on /favicon.ico [GET] [in /home/matthew/projects/microblog/venv/lib/python3.12/site-packages/flask/app.py:875]
Traceback (most recent call last):
  File "/home/matthew/projects/microblog/venv/lib/python3.12/site-packages/flask/app.py", line 917, in full_dispatch_request
    rv = self.dispatch_request()
         ^^^^^^^^^^^^^^^^^^^^^^^
  File "/home/matthew/projects/microblog/venv/lib/python3.12/site-packages/flask/app.py", line 891, in dispatch_request
    self.raise_routing_exception(req)
  File "/home/matthew/projects/microblog/venv/lib/python3.12/site-packages/flask/app.py", line 500, in raise_routing_exception
    raise request.routing_exception  # type: ignore[misc]
    ^^^^^^^^^^^^^^^^^^^^^^^^^^^^^^^
  File "/home/matthew/projects/microblog/venv/lib/python3.12/site-packages/flask/ctx.py", line 362, in match_request
    result = self.url_adapter.match(return_rule=True)  # type: ignore
             ^^^^^^^^^^^^^^^^^^^^^^^^^^^^^^^^^^^^^^^^
  File "/home/matthew/projects/microblog/venv/lib/python3.12/site-packages/werkzeug/routing/map.py", line 629, in match
    raise NotFound() from None
werkzeug.exceptions.NotFound: 404 Not Found: The requested URL was not found on the server. If you entered the URL manually please check your spelling and try again.

During handling of the above exception, another exception occurred:

Traceback (most recent call last):
  File "/home/matthew/projects/microblog/venv/lib/python3.12/site-packages/flask/app.py", line 1511, in wsgi_app
    response = self.full_dispatch_request()
               ^^^^^^^^^^^^^^^^^^^^^^^^^^^^
  File "/home/matthew/projects/microblog/venv/lib/python3.12/site-packages/flask/app.py", line 919, in full_dispatch_request
    rv = self.handle_user_exception(e)
         ^^^^^^^^^^^^^^^^^^^^^^^^^^^^^
  File "/home/matthew/projects/microblog/venv/lib/python3.12/site-packages/flask/app.py", line 802, in handle_user_exception
    return self.handle_http_exception(e)
           ^^^^^^^^^^^^^^^^^^^^^^^^^^^^^
  File "/home/matthew/projects/microblog/venv/lib/python3.12/site-packages/flask/app.py", line 777, in handle_http_exception
    return self.ensure_sync(handler)(e)  # type: ignore[no-any-return]
           ^^^^^^^^^^^^^^^^^^^^^^^^^^^^
  File "/home/matthew/projects/microblog/app/errors.py", line 6, in not_found_error
    return render_template('404.html'), 404
           ^^^^^^^^^^^^^^^^^^^^^^^^^^^
  File "/home/matthew/projects/microblog/venv/lib/python3.12/site-packages/flask/templating.py", line 149, in render_template
    template = app.jinja_env.get_or_select_template(template_name_or_list)
               ^^^^^^^^^^^^^^^^^^^^^^^^^^^^^^^^^^^^^^^^^^^^^^^^^^^^^^^^^^^
  File "/home/matthew/projects/microblog/venv/lib/python3.12/site-packages/jinja2/environment.py", line 1087, in get_or_select_template
    return self.get_template(template_name_or_list, parent, globals)
           ^^^^^^^^^^^^^^^^^^^^^^^^^^^^^^^^^^^^^^^^^^^^^^^^^^^^^^^^^
  File "/home/matthew/projects/microblog/venv/lib/python3.12/site-packages/jinja2/environment.py", line 1016, in get_template
    return self._load_template(name, globals)
           ^^^^^^^^^^^^^^^^^^^^^^^^^^^^^^^^^^
  File "/home/matthew/projects/microblog/venv/lib/python3.12/site-packages/jinja2/environment.py", line 975, in _load_template
    template = self.loader.load(self, name, self.make_globals(globals))
               ^^^^^^^^^^^^^^^^^^^^^^^^^^^^^^^^^^^^^^^^^^^^^^^^^^^^^^^^
  File "/home/matthew/projects/microblog/venv/lib/python3.12/site-packages/jinja2/loaders.py", line 138, in load
    code = environment.compile(source, name, filename)
           ^^^^^^^^^^^^^^^^^^^^^^^^^^^^^^^^^^^^^^^^^^^
  File "/home/matthew/projects/microblog/venv/lib/python3.12/site-packages/jinja2/environment.py", line 771, in compile
    self.handle_exception(source=source_hint)
  File "/home/matthew/projects/microblog/venv/lib/python3.12/site-packages/jinja2/environment.py", line 942, in handle_exception
    raise rewrite_traceback_stack(source=source)
  File "/home/matthew/projects/microblog/app/templates/404.html", line 5, in template
    <p><a href="{{ url_for('Index') }}">Back</a></p>
    ^^^^^^^^^^^^^^^^^^^^^^^^^
jinja2.exceptions.TemplateSyntaxError: Unexpected end of template. Jinja was looking for the following tags: 'endblock'. The innermost block that needs to be closed is 'block'.
2025-10-27 20:05:13,223 ERROR: Exception on /favicon.ico [GET] [in /home/matthew/projects/microblog/venv/lib/python3.12/site-packages/flask/app.py:875]
Traceback (most recent call last):
  File "/home/matthew/projects/microblog/venv/lib/python3.12/site-packages/flask/app.py", line 917, in full_dispatch_request
    rv = self.dispatch_request()
         ^^^^^^^^^^^^^^^^^^^^^^^
  File "/home/matthew/projects/microblog/venv/lib/python3.12/site-packages/flask/app.py", line 891, in dispatch_request
    self.raise_routing_exception(req)
  File "/home/matthew/projects/microblog/venv/lib/python3.12/site-packages/flask/app.py", line 500, in raise_routing_exception
    raise request.routing_exception  # type: ignore[misc]
    ^^^^^^^^^^^^^^^^^^^^^^^^^^^^^^^
  File "/home/matthew/projects/microblog/venv/lib/python3.12/site-packages/flask/ctx.py", line 362, in match_request
    result = self.url_adapter.match(return_rule=True)  # type: ignore
             ^^^^^^^^^^^^^^^^^^^^^^^^^^^^^^^^^^^^^^^^
  File "/home/matthew/projects/microblog/venv/lib/python3.12/site-packages/werkzeug/routing/map.py", line 629, in match
    raise NotFound() from None
werkzeug.exceptions.NotFound: 404 Not Found: The requested URL was not found on the server. If you entered the URL manually please check your spelling and try again.

During handling of the above exception, another exception occurred:

Traceback (most recent call last):
  File "/home/matthew/projects/microblog/venv/lib/python3.12/site-packages/flask/app.py", line 1511, in wsgi_app
    response = self.full_dispatch_request()
               ^^^^^^^^^^^^^^^^^^^^^^^^^^^^
  File "/home/matthew/projects/microblog/venv/lib/python3.12/site-packages/flask/app.py", line 919, in full_dispatch_request
    rv = self.handle_user_exception(e)
         ^^^^^^^^^^^^^^^^^^^^^^^^^^^^^
  File "/home/matthew/projects/microblog/venv/lib/python3.12/site-packages/flask/app.py", line 802, in handle_user_exception
    return self.handle_http_exception(e)
           ^^^^^^^^^^^^^^^^^^^^^^^^^^^^^
  File "/home/matthew/projects/microblog/venv/lib/python3.12/site-packages/flask/app.py", line 777, in handle_http_exception
    return self.ensure_sync(handler)(e)  # type: ignore[no-any-return]
           ^^^^^^^^^^^^^^^^^^^^^^^^^^^^
  File "/home/matthew/projects/microblog/app/errors.py", line 6, in not_found_error
    return render_template('404.html'), 404
           ^^^^^^^^^^^^^^^^^^^^^^^^^^^
  File "/home/matthew/projects/microblog/venv/lib/python3.12/site-packages/flask/templating.py", line 149, in render_template
    template = app.jinja_env.get_or_select_template(template_name_or_list)
               ^^^^^^^^^^^^^^^^^^^^^^^^^^^^^^^^^^^^^^^^^^^^^^^^^^^^^^^^^^^
  File "/home/matthew/projects/microblog/venv/lib/python3.12/site-packages/jinja2/environment.py", line 1087, in get_or_select_template
    return self.get_template(template_name_or_list, parent, globals)
           ^^^^^^^^^^^^^^^^^^^^^^^^^^^^^^^^^^^^^^^^^^^^^^^^^^^^^^^^^
  File "/home/matthew/projects/microblog/venv/lib/python3.12/site-packages/jinja2/environment.py", line 1016, in get_template
    return self._load_template(name, globals)
           ^^^^^^^^^^^^^^^^^^^^^^^^^^^^^^^^^^
  File "/home/matthew/projects/microblog/venv/lib/python3.12/site-packages/jinja2/environment.py", line 975, in _load_template
    template = self.loader.load(self, name, self.make_globals(globals))
               ^^^^^^^^^^^^^^^^^^^^^^^^^^^^^^^^^^^^^^^^^^^^^^^^^^^^^^^^
  File "/home/matthew/projects/microblog/venv/lib/python3.12/site-packages/jinja2/loaders.py", line 138, in load
    code = environment.compile(source, name, filename)
           ^^^^^^^^^^^^^^^^^^^^^^^^^^^^^^^^^^^^^^^^^^^
  File "/home/matthew/projects/microblog/venv/lib/python3.12/site-packages/jinja2/environment.py", line 771, in compile
    self.handle_exception(source=source_hint)
  File "/home/matthew/projects/microblog/venv/lib/python3.12/site-packages/jinja2/environment.py", line 942, in handle_exception
    raise rewrite_traceback_stack(source=source)
  File "/home/matthew/projects/microblog/app/templates/404.html", line 5, in template
    <p><a href="{{ url_for('Index') }}">Back</a></p>
    ^^^^^^^^^^^^^^^^^^^^^^^^^
jinja2.exceptions.TemplateSyntaxError: Unexpected end of template. Jinja was looking for the following tags: 'endblock'. The innermost block that needs to be closed is 'block'.
